Workbook
Name Produtos: Table_Produtos[PRODUTO]
Name Serviços: Table_Serviços[SERVIÇO]

Sheet To Do
A1: DATE | B1: TASK | C1: OBS | D1: STATUS
A2: 46035 | B2: Add e-mail Cia Beal | D2: DONE
A3: 46126 | B3: Alimentar Base - Serviços & Produtos | D3: DONE
A4: 46038 | B4: Anderson - ASO | C4: Cesla | D4: DONE
A5: 46038 | B5: Anderson - CNH/RG/CPF | C5: Cesla | D5: DONE
A6: 46038 | B6: Anderson - NR12 | C6: Cesla | D6: DONE
A7: 46038 | B7: Anderson - OS/EPI | C7: Cesla | D7: DONE
A8: 46084 | B8: Aprovação - Baston | C8: OS #1555 | D8: DONE
A9: 46072 | B9: Aprovação - Costantini | C9: OS #1533 | D9: DONE
A10: 46072 | B10: Aprovação - Costantini | C10: OS #1534 | D10: DONE
A11: 46055 | B11: Aprovação - Curitiba Business | C11: OS #1265 | D11: DONE
A12: 46057 | B12: Aprovação - Neoortho Thá | C12: OS #1364 | D12: DONE
A13: 46134 | B13: Aprovação - Netcom | C13: OS #1777 | D13: DONE
A14: 46127 | B14: Aprovação - Renault | C14: OS #1757 | D14: DONE
A15: 46105 | B15: Aprovação - Selection | C15: OS #1512 | D15: DONE
... A17: 46071 | B17: Aprovação - Votorantim | C17: OS #1506 | D17: DONE
A18: 46049 | B18: Assinar - Contrato Clinimêrces | D18: DONE
A19: 46079 | B19: Atualizar - Condor São José | C19: OS #1532 | D19: DONE
A20: 46119 | B20: Atualizar - Docs SG3 | D20: DONE
A21: 46042 | B21: Atualizar - Hotel Confiance | C21: OS #1336 | D21: DONE
A22: 46035 | B22: Atualizar - JRM | C22: OS #1364 | D22: DONE
A23: 46073 | B23: Atualizar - Lu cardoso | C23: OS #1544 | D23: DONE
A24: 46079 | B24: Atualizar - Mondelez | C24: OS #1575 | D24: DONE
A25: 46114 | B25: Atualizar - Mondelez | C25: OS #1613 | D25: DONE
A26: 46035 | B26: Atualizar - Mueller | C26: OS #1375 | D26: DONE
A27: 46050 | B27: Atualizar - Oftalmologia | C27: OS #1437 | D27: DONE
A28: 46035 | B28: Atualizar - OS #1120 | C28: OS #1385 | D28: DONE
A29: 46038 | B29: Atualizar - Sesi | C29: 0808/25 - 1054/25 | D29: DONE
A30: 46065 | B30: Atualizar - Sicredi | C30: OS #1254 | D30: DONE
A31: 46036 | B31: Atualizar - Templates email | D31: DONE
A32: 46072 | B32: Atualizar - Tetrapak | C32: OS #1209 | D32: DONE
A33: 46038 | B33: Atualizar - Vencimento Docs | D33: DONE
A34: 46084 | B34: Cadastrar - Calpie | D34: DONE
A35: 46076 | B35: Cadastrar - Jatoba | D35: DONE
A36: 46009 | B36: Cancelar Notas - Lightera | C36: NFS-e 60 | D36: DONE
A37: 46073 | B37: Cancelar Notas - Manusa | C37: OS #5249 | D37: DONE
A38: 46064 | B38: Cancelar Notas - Neoortho | C38: OS #1364 | D38: DONE
A39: 46006 | B39: Cancelar Notas - Rissi | C39: NF-e 5381 | D39: DONE
A40: 46065 | B40: Cancelar Notas - Sicredi | C40: OS #1254 | D40: DONE
A41: 46064 | B41: Carta Correção NF-e 5442 | C41: OS #1254 | D41: DONE
...

Sheet NC Portas
D1: NF-e PRODUTO | G1: NFS-e SERVIÇO
A2: OS | B2: CLIENTE | C2: TOTAL | D2: NF-e | E2: VALOR | F2: Status P | G2: NFS-e | H2: DPS | I2: VALOR SERVIÇO | J2: Status S | K2: OK | L2: REF | M2: OBSERVAÇÕES
A3: 427 | B3: Sig | C3: 5629 | D3: 5329 | E3: 3379 | F3: Emitida | G3: 5 | H3: 15 | I3: 2250 | J3: Emitida | K3: =IF(AND(D3<>"", G3<>""), "OK", "") -> OK | L3: 0978/25
A4: 431 | B4: Sig | C4: 3842.6 | D4: 5330 | E4: 1722.3 | F4: Emitida | G4: 6 | H4: 18 | I4: 2120 | J4: Emitida | K4: =IF(AND(D4<>"", G4<>""), "OK", "") -> OK | L4: 0977/25
A5: 450 | B5: In Haus | C5: 1280 | D5: - | E5: - | F5: - | G5: 7 | H5: 13 | I5: 1280 | J5: Emitida | K5: =IF(AND(D5<>"", G5<>""), "OK", "") -> OK | L5: 1069/25
A6: 1227 | B6: Triermach | C6: 1613 | D6: 5349 | E6: 723 | F6: Emitida | G6: 8 | H6: 24 | I6: 890 | J6: Emitida | K6: =IF(AND(D6<>"", G6<>""), "OK", "") -> OK | L6: -
A7: 390 | B7: Sig | C7: 3586.3 | D7: 5257 | E7: 1898.8 | F7: Emitida | G7: 9 | H7: 19 | I7: 1687.5 | J7: Emitida | K7: =IF(AND(D7<>"", G7<>""), "OK", "") -> OK | L7: 0845/25
A8: 1096 | B8: In Haus | C8: 1588 | D8: 5353 | E8: 698 | F8: Emitida | G8: 12 | H8: 27 | I8: 890 | J8: Emitida | K8: =IF(AND(D8<>"", G8<>""), "OK", "") -> OK | L8: -
A9: 55 | B9: Mondelez | C9: 28360.9 | D9: 5011 | E9: 22940.9 | F9: Emitida | G9: 13 | H9: 28 | I9: 5420 | J9: Emitida | K9: =IF(AND(D9<>"", G9<>""), "OK", "") -> OK | L9: 0115/25
A10: 317 | B10: Mondelez | C10: 1590 | D10: - | E10: - | F10: - | G10: 14 | H10: 29 | I10: 1590 | J10: Emitida | K10: =IF(AND(D10<>"", G10<>""), "OK", "") -> OK | L10: 0317/25
A11: 365 | B11: Volkswagen | C11: 32346.3 | D11: 5328 | E11: 27751.3 | F11: Emitida | G11: 15 | H11: 7 | I11: 4595 | J11: Cancelada | K11: OK | L11: 0455/25 | M11: Cancelada e reemitida na OS #1276
A12: 401 | B12: Mondelez | C12: 33341.4 | D12: 5347 | E12: 27681.4 | F12: Emitida | G12: 17 | H12: 31 | I12: 5660 | J12: Emitida | K12: =IF(AND(D12<>"", G12<>""), "OK", "") -> OK | L12: 0947/25
A13: 1250 | B13: DVS | C13: 890 | D13: - | E13: - | F13: - | G13: 18 | H13: 32 | I13: 890 | J13: Emitida | K13: =IF(AND(D13<>"", G13<>""), "OK", "") -> OK | L13: -
A14: 424 | B14: API SPE 46 | C14: 26180 | D14: 5354 | E14: 10820 | F14: Emitida | G14: 19 | H14: 33 | I14: 15360 | J14: Emitida | K14: =IF(AND(D14<>"", G14<>""), "OK", "") -> OK | L14: 1015/25 | M14: 1006/25
A15: 436 | B15: Renault | C15: 5180 | D15: 5351 | E15: 3360 | F15: Emitida | G15: 21 | H15: 35 | I15: 1820 | J15: Emitida | K15: =IF(AND(D15<>"", G15<>""), "OK", "") -> OK | L15: 1051/25
A16: 1044 | B16: In Haus | C16: 1126.76 | D16: - | E16: - | F16: - | G16: 22 | H16: 36 | I16: 1126.76 | J16: Emitida | K16: =IF(AND(D16<>"", G16<>""), "OK", "") -> OK | L16: -
A17: 1185 | B17: In Haus | C17: 1790 | D17: - | E17: - | F17: - | G17: 23 | H17: 37 | I17: 1790 | J17: Emitida | K17: =IF(AND(D17<>"", G17<>""), "OK", "") -> OK | L17: -
A18: 1123 | B18: Mondelez | C18: 29734.3 | D18: 5346 | E18: 23314.3 | F18: Emitida | G18: 24 | H18: 38 | I18: 6420 | J18: Emitida | K18: =IF(AND(D18<>"", G18<>""), "OK", "") -> OK | L18: -
A19: 770 | B19: Gold | C19: 10560 | D19: 5355 | E19: 5460 | F19: Emitida | G19: 26 | H19: 11 | I19: 4284 | J19: Emitida | K19: =IF(AND(D19<>"", G19<>""), "OK", "") -> OK | L19: -
A20: 1263 | B20: Liga das Senhoras | C20: 890 | D20: - | E20: - | F20: - | G20: 28 | H20: 41 | I20: 890 | J20: Emitida | K20: =IF(AND(D20<>"", G20<>""), "OK", "") -> OK | L20: -
A21: 1145 | B21: Ebanx | C21: 16247.15 | D21: 5359 | E21: 6447.15 | F21: Emitida | G21: 29 | H21: 42 | I21: 9800 | J21: Emitida | K21: =IF(AND(D21<>"", G21<>""), "OK", "") -> OK | L21: -
A22: 1251 | B22: Callfarma | C22: 1720 | D22: 5360 | E22: 830 | F22: Emitida | G22: 30 | H22: 43 | I22: 890 | J22: Emitida | K22: =IF(AND(D22<>"", G22<>""), "OK", "") -> OK | L22: -
A23: 1248 | B23: Hospital Union | C23: 980 | D23: - | E23: - | F23: - | G23: 31 | H23: 44 | I23: 980 | J23: Emitida | K23: =IF(AND(D23<>"", G23<>""), "OK", "") -> OK | L23: -
A24: 280 | B24: Graham Pack | C24: 32138.53 | D24: 5248 | E24: 29138.53 | F24: Emitida | G24: 32 | H24: 46 | I24: 3000 | J24: Emitida | K24: =IF(AND(D24<>"", G24<>""), "OK", "") -> OK | L24: 0989/24
A25: 1276 | B25: Volkswagen | C25: 32346.3 | D25: - | E25: - | F25: - | G25: 33 | H25: 13 | I25: 32346.3 | J25: Emitida | K25: =IF(AND(D25<>"", G25<>""), "OK", "") -> OK | L25: 365
A26: 1283 | B26: Filial 28 - Condor | C26: 920 | D26: - | E26: - | F26: - | G26: 36 | H26: 51 | I26: 920 | J26: Emitida | K26: =IF(AND(D26<>"", G26<>""), "OK", "") -> OK | L26: -
A27: 1284 | B27: Filial 01 - Condor | C27: 1315.7 | D27: 5374 | E27: 665.7 | F27: Emitida | G27: 37 | H27: 52 | I27: 650 | J27: Emitida | K27: =IF(AND(D27<>"", G27<>""), "OK", "") -> OK | L27: -
A28: 327 | B28: Renault | C28: 6468.4 | D28: 5200 | E28: 2918.4 | F28: Emitida | G28: 38 | H28: 15 | I28: 3550 | J28: Emitida | K28: =IF(AND(D28<>"", G28<>""), "OK", "") -> OK | L28: 0645/25
A29: 976 | B29: Sig | C29: 1442.5 | D29: - | E29: - | F29: - | G29: 39 | H29: 17 | I29: 1442.5 | J29: Emitida | K29: =IF(AND(D29<>"", G29<>""), "OK", "") -> OK | L29: -
A30: 399 | B30: Renault | C30: 7644.5 | D30: 5371 | E30: 1333.2 | F30: Emitida | G30: 40 | H30: 19 | I30: 6311.3 | J30: Emitida | K30: =IF(AND(D30<>"", G30<>""), "OK", "") -> OK | L30: 0646/25
A31: 1259 | B31: Hospital Santa Cruz | C31: 890 | D31: - | E31: - | F31: - | G31: 41 | H31: 53 | I31: 890 | J31: Emitida | K31: =IF(AND(D31<>"", G31<>""), "OK", "") -> OK | L31: -
A32: 1287 | B32: Centro Empresarial Glaser | C32: 890 | D32: - | E32: - | F32: - | G32: 42 | H32: 54 | I32: 890 | J32: Emitida | K32: =IF(AND(D32<>"", G32<>""), "OK", "") -> OK | L32: -
A33: 1272 | B33: L&F Vidros | C33: 6160 | D33: 5376 | E33: 1240 | F33: Cancelada | G33: 43 | H33: 55 | I33: 4920 | J33: Cancelada | K33: OFF | L33: - | M33: Cancelada
A34: 418 | B34: L&F Vidros | C34: 7445 | D34: 5377 | E34: 1180 | F34: Cancelada | G34: 44 | H34: 56 | I34: 6265 | J34: Cancelada | K34: OFF | L34: 0945/25 | M34: Cancelada
A35: 1272 | B35: L&F Vidros | C35: 6160 | D35: 5376 | E35: 1240 | F35: Cancelada | G35: 45 | H35: 21 | I35: 4674 | J35: Cancelada | K35: OFF | L35: - | M35: Cancelada
A36: 418 | B36: L&F Vidros | C36: 7445 | D36: 5377 | E36: 1180 | F36: Cancelada | G36: 46 | H36: 23 | I36: 5951.75 | J36: Cancelada | K36: OFF | L36: - | M36: Cancelada
A37: 1269 | B37: JJGC | C37: 890 | D37: - | E37: - | F37: - | G37: 47 | H37: 57 | I37: 890 | J37: Emitida | K37: =IF(AND(D37<>"", G37<>""), "OK", "") -> OK | L37: -
A38: 332 | B38: JJGC | C38: 33874.91 | D38: 5372 | E38: 28469.41 | F38: Emitida | G38: 49 | H38: 58 | I38: 5405.5 | J38: Emitida | K38: =IF(AND(D38<>"", G38<>""), "OK", "") -> OK | L38: 0593/25
A39: 1118 | B39: JJGC | C39: 17644.3 | D39: 5369 | E39: 12901 | F39: Emitida | G39: 50 | H39: 59 | I39: 4743.3 | J39: Emitida | K39: =IF(AND(D39<>"", G39<>""), "OK", "") -> OK
A40: 1272 | B40: L&F Vidros | C40: 6160 | D40: 5378 | E40: 1240 | F40: Emitida | G40: 51 | H40: 25 | I40: 4132.8 | J40: Emitida | K40: =IF(AND(D40<>"", G40<>""), "OK", "") -> OK | L40: -
...

Sheet Formulas
A1: PRODUTO | E1: TEXT | G1: DESCRIÇÃO | H1: FORMULA
A2: Vidro Temperado Incolor 10mm | E2: ANDAR 01 COND NEW ZEALAND EMPRESAR | G2: Formula Calculo Valor Total m² | H2: Valor Total m² = Area Total m² * Valor m²
A3: VALOR M² | E3: Proper | G3: Formula Calculo Area Total m² | H3: Area Total m² = Largura * Comprimento
A4: MEDIDAS | B4: VALOR | C4: X 2 | E4: =PROPER($E$2) -> Andar 01 Cond New Zealand Empresar | G4: Formula Deslocamento | H4: Distância Km * 2 * 3
A5: Largura | B5: 2.4 | C5: =B5*2 -> 4.8 | E5: lower | G5: Formula Calculo Peso Vidro | H5: Peso Total = Largura * Comprimento * Espessura/kg
A6: Comprimento | B6: 2.2 | C6: =B6*2 -> 4.4 | E6: =LOWER($E$2) -> andar 01 cond new zealand empresar | G6: Formula Calculo PVC | H6: (Largura/2) * Altura * Valor m²
A7: Espessura/kg | B7: =IFERROR(VLOOKUP($C$8,Valor_M²[],3,FALSE),"-") -> - | C7: - | E7: UPPER | G7: Formula Acomodação | H7: ((350 * Dias) + (100 * Dias * Func)) * (1 + 10 %)
A8: Area Total m² | B8: =IFERROR(B5*B6," ") -> 5.28 | C8: =B8*2 -> 10.56 | E8: =UPPER($E$2) -> ANDAR 01 COND NEW ZEALAND EMPRESAR | G8: Custo Serviço Prestado | H8: (Funcionários * Horas * CHH) + (Horas * CHV) + (KM * Valor KM) + Materiais
A9: Valor m² | B9: =IFERROR(VLOOKUP(A2,Valor_M²[#All],2,),"-") -> 470 | C9: =B9*2 -> 940 | G9: Custo Hora Homem | H9: (Folha + Encargos) / Horas Produtivas
A10: Valor Total m² | B10: =IFERROR(B8*B9," ") -> 2481.6 | C10: =B10*2 -> 4963.2 | G10: Custo Hora Veiculo | H10: (Manutenção + Depreciação) / Horas Produtivas
A11: Peso Total Vidro | B11: =IFERROR($D$12*$D$13*$D$14," ") -> 0 | C11: =B11*2 -> 0
A13: DESLOCAMENTO | C13: X 2 | E13: CSP
A14: Distância KM: | B14: 500 | C14: =B14*2 -> 1000 | E14: =_xlfn.LET(_xlpm.V_Folha,CSP!$B$26,_xlpm.V_Frota,CSP!$B$27,_xlpm.H_Produtiva,CSP!$B$28,_xlpm.K_Valor,CSP!$B$29,_xlpm.P_Imposto,CSP!$B$30,_xlpm.S_Quant,CSP!$B$31,_xlpm.S_Horas,CSP!$B$32,_xlpm.S_Dist,CSP!$B$33,_xlpm.S_Mat,CSP!$B$34,_xlpm.CHH,_xlpm.V_Folha/_xlpm.H_Produtiva,_xlpm.CHV,_xlpm.V_Frota/_xlpm.H_Produtiva,_xlpm.Custo_Base,(_xlpm.S_Quant*_xlpm.S_Horas*_xlpm.CHH)+(_xlpm.S_Horas*_xlpm.CHV)+(_xlpm.S_Dist*_xlpm.K_Valor)+_xlpm.S_Mat,_xlpm.CSP_Final,_xlpm.Custo_Base/(1-_xlpm.P_Imposto),_xlpm.CSP_Final) -> 1210.2277
A15: Valor: | B15: =B14*2*3 -> 3000 | C15: =B15*2 -> 6000
A17: CSP
A18: Funcionários | B18: 2
A19: Horas | B19: 8
A20: Distância | B20: 10
A21: Material | B21: 50
A23: ACOMODAÇÃO
A24: Dias | B24: 3
A25: Funcionários | B25: 2
A26: Valor | B26: =((350*B24)+(100*B24*B25))*(1+10%) -> 1815
A28: PVC
A29: Valor: | B29: =IFERROR((B5/2)*B6*B9," ") -> 1240.8
A31: PORCENTAGEM | B31: ADD | C31: DISCOUNT
A32: Valor: | B32: 546 | C32: =B32 -> 546
A33: Porcentagem | B33: 0.1 | C33: 0.05
A34: Total | B34: =B32*(1+B33) -> 600.6 | C34: =C32*(1-C33) -> 518.7
A36: OS | B36: NF | C36: STATUS
A37: 1474 | B37: {=_xlfn.UNIQUE(_xlfn._xlws.FILTER(_xlfn.CHOOSECOLS(_xlfn.VSTACK(NFe_NC[],NFSe_NC[],NFe_Nice[],NFSe_Nice[]),4),_xlfn.CHOOSECOLS(_xlfn.VSTACK(NFe_NC[],NFSe_NC[],NFe_Nice[],NFSe_Nice[]),1)=A37,"No NF Found"))} -> 168 | C37: {=_xlfn.MAP(_xlfn.ANCHORARRAY(B37), _xlfn.LAMBDA(_xlpm.nfe, IF(_xlpm.nfe="No NF-e Found", "", _xlfn.LET( _xlpm.all_data, _xlfn.VSTACK( _xlfn.CHOOSECOLS(NFe_NC[], 4, 10), _xlfn.CHOOSECOLS(NFe_Nice[], 4, 10), _xlfn.CHOOSECOLS(NFSe_NC[], 4, 9), _xlfn.CHOOSECOLS(NFSe_Nice[], 4, 9) ), _xlfn.XLOOKUP(_xlpm.nfe, _xlfn.CHOOSECOLS(_xlpm.all_data, 1), _xlfn.CHOOSECOLS(_xlpm.all_data, 2), "No STATUS Found") ) ) ))} -> Emitida

Sheet Preços
A2: PRODUTOS | C2: Preço Máximo | D2: =_xlfn.MAXIFS(Table_Produtos[V. UNIT],Table_Produtos[PRODUTO],$A$3) -> 774 | J2: SERVIÇOS | L2: Preço Máximo | M2: =_xlfn.MAXIFS(Table_Serviços[V. UNIT],Table_Serviços[SERVIÇO],$J$3) -> 1620
A3: CORREIA DE TRAÇÃO 14MM - BRAVO / VISIO+ 125 | C3: Preço Médio | D3: =AVERAGEIF(Table_Produtos[PRODUTO],$A$3,Table_Produtos[V. UNIT]) -> 774 | J3: SERVIÇO DE PINTURA / ANODIZAÇÃO DE OPERADOR / FOLHA | L3: Preço Médio | M3: =AVERAGEIF(Table_Serviços[SERVIÇO],$J$3,Table_Serviços[V. UNIT]) -> 758.61702
C4: Preço Minimo | D4: =_xlfn.MINIFS(Table_Produtos[V. UNIT],Table_Produtos[PRODUTO],$A$3) -> 774 | L4: Preço Minimo | M4: =_xlfn.MINIFS(Table_Serviços[V. UNIT],Table_Serviços[SERVIÇO],$J$3) -> 430
A6: PRODUTO | B6: UND | C6: QTDE. | D6: NCM | E6: V. UNIT. | F6: V. TOTAL | G6: CLIENTE | H6: OS | J6: SERVIÇO | K6: QTDE | L6: V. UNIT. | M6: V. TOTAL | N6: CLIENTE | O6: OS
A7: {=_xlfn._xlws.SORT(_xlfn._xlws.FILTER(Table_Produtos[],Table_Produtos[PRODUTO]=$A$3,"error"),5,-1)} -> CORREIA DE TRAÇÃO 14MM - BRAVO / VISIO+ 125 | B7: (Un) | C7: 1 | D7: 40029990 | E7: 774 | F7: 774 | G7: EQS Engenharia | H7: 1771 | J7: {=_xlfn._xlws.SORT(_xlfn._xlws.FILTER(Table_Serviços[],Table_Serviços[SERVIÇO]=$J$3,"error"),3,-1)} -> SERVIÇO DE PINTURA / ANODIZAÇÃO DE OPERADOR / FOLHA | K7: 1.00 | L7: 1620 | M7: 1620 | N7: Irmãos Madalosso | O7: 1754
A8: CORREIA DE TRAÇÃO 14MM - BRAVO / VISIO+ 125 | B8: (Un) | C8: 1 | D8: 40029990 | E8: 774 | F8: 774 | G8: Multi Turbo | H8: 1803 | J8: SERVIÇO DE PINTURA / ANODIZAÇÃO DE OPERADOR / FOLHA | K8: 1.00 | L8: 1390 | M8: 1390 | N8: Rissi Fachadas | O8: 1802
J9: SERVIÇO DE PINTURA / ANODIZAÇÃO DE OPERADOR / FOLHA | K9: 1.00 | L9: 1230 | M9: 1230 | N9: Irmãos Madalosso | O9: 1755
J10: SERVIÇO DE PINTURA / ANODIZAÇÃO DE OPERADOR / FOLHA | K10: 1.00 | L10: 1150 | M10: 1150 | N10: Supermercado Jacomar | O10: 1707
J11: SERVIÇO DE PINTURA / ANODIZAÇÃO DE OPERADOR / FOLHA | K11: 1.00 | L11: 980 | M11: 980 | N11: Supermercado Jacomar | O11: 1706
J12: SERVIÇO DE PINTURA / ANODIZAÇÃO DE OPERADOR / FOLHA | K12: 1.00 | L12: 890 | M12: 890 | N12: Selection Locadora | O12: 1701
J13: SERVIÇO DE PINTURA / ANODIZAÇÃO DE OPERADOR / FOLHA | K13: 1.00 | L13: 890 | M13: 890 | N13: Rissi Fachadas | O13: 1750
J14: SERVIÇO DE PINTURA / ANODIZAÇÃO DE OPERADOR / FOLHA | K14: 1.00 | L14: 890 | M14: 890 | N14: Irmãos Madalosso | O14: 1752
J15: SERVIÇO DE PINTURA / ANODIZAÇÃO DE OPERADOR / FOLHA | K15: 1.00 | L15: 890 | M15: 890 | N15: Irmãos Madalosso | O15: 1753
J16: SERVIÇO DE PINTURA / ANODIZAÇÃO DE OPERADOR / FOLHA | K16: 1.00 | L16: 890 | M16: 890 | N16: Vidraçaria Passarela | O16: 1790
J17: SERVIÇO DE PINTURA / ANODIZAÇÃO DE OPERADOR / FOLHA | K17: 1.00 | L17: 850 | M17: 850 | N17: Lavitta Engenharia | O17: 1764
J18: SERVIÇO DE PINTURA / ANODIZAÇÃO DE OPERADOR / FOLHA | K18: 1.00 | L18: 850 | M18: 850 | N18: Giben do Brasil | O18: 1801
J19: SERVIÇO DE PINTURA / ANODIZAÇÃO DE OPERADOR / FOLHA | K19: 1.00 | L19: 790 | M19: 790 | N19: Nova Vidraçaria | O19: 1723
J20: SERVIÇO DE PINTURA / ANODIZAÇÃO DE OPERADOR / FOLHA | K20: 1.00 | L20: 790 | M20: 790 | N20: AD&N Consultoria | O20: 1732
... J53: SERVIÇO DE PINTURA / ANODIZAÇÃO DE OPERADOR / FOLHA | K53: 3.00 | L53: 430 | M53: 1290 | N53: SECOVIMED | O53: 1726

Sheet Configurador

Sheet NF-e NC
A1: OS | B1: CLIENTE | C1: TOTAL OS | D1: NF-e | E1: VALOR NF-e | F1: CFOP | G1: NATUREZA | H1: CHAVE | I1: EMISSÃO | J1: STATUS | K1: OBSERVAÇÕES | L1: PDF | M1: XML
A2: 115 | B2: Mondelez Brasil Ltda | C2: 28360.9 | D2: 5011 | E2: 22940.9 | F2: 5102 | G2: =VLOOKUP(F2,CFOP[],2,FALSE) -> Venda de mercadoria adquirida ou recebida de terceiros | H2: 41250313929397000142550010000050111000865610 | I2: 45740 | J2: Emitida | L2: OK | M2: OK
A3: 327 | B3: Renault do Brasil Ltda | C3: 6468.4 | D3: 5200 | E3: 2918.4 | F3: 5102 | G3: =VLOOKUP(F3,CFOP[],2,FALSE) -> Venda de mercadoria adquirida ou recebida de terceiros | H3: 41250813929397000142550010000052001928889133 | I3: 45870 | J3: Emitida | L3: OK | M3: OK
A4: 280 | B4: Graham Packaging do Brasil Indústria e Comércio Ltda | C4: 32138.53 | D4: 5248 | E4: 29138.53 | F4: 5101 | G4: =VLOOKUP(F4,CFOP[],2,FALSE) -> Venda de produção do estabelecimento | H4: 41250913929397000142550010000052481805589643 | I4: 45905 | J4: Emitida | L4: OK | M4: OK
A5: 390 | B5: Sig Combibloc do Brasil Ltda | C5: 3586.3 | D5: 5257 | E5: 1898.8 | F5: 5102 | G5: =VLOOKUP(F5,CFOP[],2,FALSE) -> Venda de mercadoria adquirida ou recebida de terceiros | H5: 41250913929397000142550010000052571482726007 | I5: 45916 | J5: Emitida | L5: OK | M5: OK
A6: 393 | B6: Sig Combibloc do Brasil Ltda | C6: 7558 | D6: 5292 | E6: 6038 | F6: 5102 | G6: =VLOOKUP(F6,CFOP[],2,FALSE) -> Venda de mercadoria adquirida ou recebida de terceiros | H6: 41251013929397000142550010000052921412199589 | I6: 45938 | J6: Emitida | L6: OK | M6: OK
A7: 446 | B7: Condomínio Edifício Residence Batel | C7: 178 | D7: 5301 | E7: 178 | F7: 5102 | G7: =VLOOKUP(F7,CFOP[],2,FALSE) -> Venda de mercadoria adquirida ou recebida de terceiros | H7: 41251013929397000142550010000053011287202517 | I7: 45945 | J7: Emitida
A8: 447 | B8: Sindicato Dos Empregados Em Estabelecimentos Bancários | C8: 190 | D8: 5302 | E8: 190 | F8: 5102 | G8: =VLOOKUP(F8,CFOP[],2,FALSE) -> Venda de mercadoria adquirida ou recebida de terceiros | H8: 41251013929397000142550010000053021287202514 | I8: 45945 | J8: Emitida
A9: - | B9: MetalFim Tratamentos de Superficie Ltda | C9: 6500 | D9: 5303 | E9: 6500 | F9: 5102 | G9: =VLOOKUP(F9,CFOP[],2,FALSE) -> Venda de mercadoria adquirida ou recebida de terceiros | H9: 41251013929397000142550010000053031287202511 | I9: 45945 | J9: Cancelada
A10: - | B10: MetalFim Tratamentos de Superficie Ltda | C10: 7800 | D10: 5304 | E10: 7800 | F10: 5901 | G10: =VLOOKUP(F10,CFOP[],2,FALSE) -> Remessa para industrialização por encomenda | H10: 41251013929397000142550010000053041287202519 | I10: 45945 | J10: Emitida
A11: 377 | B11: Netcom Construtora Ltda | C11: 1919.5 | D11: 5305 | E11: 1294.5 | F11: 5102 | G11: =VLOOKUP(F11,CFOP[],2,FALSE) -> Venda de mercadoria adquirida ou recebida de terceiros | H11: 41251013929397000142550010000053051295202511 | I11: 45953 | J11: Emitida
A12: 455 | B12: Luciana B G Der Bedrossian | C12: 908.7 | D12: 5306 | E12: 908.7 | F12: 5102 | G12: =VLOOKUP(F12,CFOP[],2,FALSE) -> Venda de mercadoria adquirida ou recebida de terceiros | H12: 41251013929397000142550010000053061287202513 | I12: 45945 | J12: Emitida
A13: 425 | B13: Mondelez Brasil Ltda | C13: 10600.47 | D13: 5307 | E13: 10600.47 | F13: 5102 | G13: =VLOOKUP(F13,CFOP[],2,FALSE) -> Venda de mercadoria adquirida ou recebida de terceiros | H13: 41251013929397000142550010000053071288202514 | I13: 45946 | J13: Emitida
A14: 410 | B14: Madeshopping Investimentos e Participações Ltda | C14: 9180 | D14: 5308 | E14: 4185 | F14: 5102 | G14: =VLOOKUP(F14,CFOP[],2,FALSE) -> Venda de mercadoria adquirida ou recebida de terceiros | H14: 41251013929397000142550010000053081288202511 | I14: 45946 | J14: Emitida
A15: 439 | B15: União Champagnat de Educação | C15: 1860 | D15: 5309 | E15: 970 | F15: 5102 | G15: =VLOOKUP(F15,CFOP[],2,FALSE) -> Venda de mercadoria adquirida ou recebida de terceiros | H15: 41251013929397000142550010000053091289202512 | I15: 45947 | J15: Emitida
A16: 456 | B16: Renault do Brasil Ltda | C16: 2524.2 | D16: 5310 | E16: 2374.2 | F16: 5102 | G16: =VLOOKUP(F16,CFOP[],2,FALSE) -> Venda de mercadoria adquirida ou recebida de terceiros | H16: 41251013929397000142550010000053101294202518 | I16: 45952 | J16: Cancelada
A17: - | B17: Calpie Pinturas Industriais Ltda | C17: 2150 | D17: 5311 | E17: 2150 | F17: 5901 | G17: =VLOOKUP(F17,CFOP[],2,FALSE) -> Remessa para industrialização por encomenda | H17: 41251013929397000142550010000053111292202518 | I17: 45950 | J17: Emitida
A18: 452 | B18: Ouro Verde Participações S/A | C18: 1186.5 | D18: 5312 | E18: 1186.5 | F18: 5102 | G18: =VLOOKUP(F18,CFOP[],2,FALSE) -> Venda de mercadoria adquirida ou recebida de terceiros | H18: 41251013929397000142550010000053121292202515 | I18: 45950 | J18: Emitida
A19: 457 | B19: Condomínio Edifício Residence Batel | C19: 1030.8 | D19: 5313 | E19: 1030.8 | F19: 5102 | G19: =VLOOKUP(F19,CFOP[],2,FALSE) -> Venda de mercadoria adquirida ou recebida de terceiros | H19: 41251013929397000142550010000053131293202516 | I19: 45951 | J19: Emitida
A20: 1157 | B20: Jockey Plaza Shopping Center | C20: 1613 | D20: 5314 | E20: 723 | F20: 5102 | G20: =VLOOKUP(F20,CFOP[],2,FALSE) -> Venda de mercadoria adquirida ou recebida de terceiros | H20: 41251013929397000142550010000053141293202513 | I20: 45951 | J20: Emitida
A21: 422 | B21: Pátio Batel Shopping Ltda | C21: 2098.65 | D21: 5315 | E21: 2098.65 | F21: 5102 | G21: =VLOOKUP(F21,CFOP[],2,FALSE) -> Venda de mercadoria adquirida ou recebida de terceiros | H21: 41251013929397000142550010000053151293202510 | I21: 45951 | J21: Emitida
A22: 1160 | B22: Parth Administração e Empreendimentos Ltda | C22: 894.9 | D22: 5316 | E22: 894.9 | F22: 5102 | G22: =VLOOKUP(F22,CFOP[],2,FALSE) -> Venda de mercadoria adquirida ou recebida de terceiros | H22: 41251013929397000142550010000053161293202518 | I22: 45951 | J22: Emitida
A23: 1117 | B23: HCL Hotéis Ltda | C23: 8614.9 | D23: 5317 | E23: 7454.9 | F23: 5102 | G23: =VLOOKUP(F23,CFOP[],2,FALSE) -> Venda de mercadoria adquirida ou recebida de terceiros | H23: 41251013929397000142550010000053171293202515 | I23: 45951 | J23: Emitida
A24: 440 | B24: Condomínio do Edifício Philadelphia | C24: 945 | D24: 5318 | E24: 945 | F24: 5102 | G24: =VLOOKUP(F24,CFOP[],2,FALSE) -> Venda de mercadoria adquirida ou recebida de terceiros | H24: 41251013929397000142550010000053181294202516 | I24: 45952 | J24: Emitida
A25: 407 | B25: Condomínio do Edifício Philadelphia | C25: 2980.8 | D25: 5319 | E25: 2980.8 | F25: 5102 | G25: =VLOOKUP(F25,CFOP[],2,FALSE) -> Venda de mercadoria adquirida ou recebida de terceiros | H25: 41251013929397000142550010000053191294202513 | I25: 45952 | J25: Emitida
A26: 441 | B26: Madero Industria e Comércio S.A | C26: 760 | D26: 5320 | E26: 510 | F26: 6102 | G26: =VLOOKUP(F26,CFOP[],2,FALSE) -> Venda de mercadoria adquirida ou recebida de terceiros | H26: 41251013929397000142550010000053201294202514 | I26: 45952 | J26: Emitida
A27: 378 | B27: Netcom Construtora Ltda | C27: 8486 | D27: 5321 | E27: 4036 | F27: 5102 | G27: =VLOOKUP(F27,CFOP[],2,FALSE) -> Venda de mercadoria adquirida ou recebida de terceiros | H27: 41251013929397000142550010000053211295202515 | I27: 45953 | J27: Emitida
A28: - | B28: MetalFim Tratamentos de Superficie Ltda | C28: 1540 | D28: 5322 | E28: 1540 | F28: 5901 | G28: =VLOOKUP(F28,CFOP[],2,FALSE) -> Remessa para industrialização por encomenda | H28: 41251013929397000142550010000053221295202512 | I28: 45953 | J28: Cancelada
A29: 456 | B29: Renault do Brasil Ltda | C29: 2524.2 | D29: 5323 | E29: 2524.2 | F29: 5102 | G29: =VLOOKUP(F29,CFOP[],2,FALSE) -> Venda de mercadoria adquirida ou recebida de terceiros | H29: 41251013929397000142550010000053231295202510 | I29: 45953 | J29: Emitida
A30: - | B30: Fast Pintura a Pó Ltda | C30: 1540 | D30: 5324 | E30: 1540 | F30: 5901 | G30: =VLOOKUP(F30,CFOP[],2,FALSE) -> Remessa para industrialização por encomenda | H30: 41251013929397000142550010000053241295202517 | I30: 45953 | J30: Emitida
A31: 451 | B31: Netcom Construtora Ltda | C31: 4785.2 | D31: 5325 | E31: 4785.2 | F31: 5102 | G31: =VLOOKUP(F31,CFOP[],2,FALSE) -> Venda de mercadoria adquirida ou recebida de terceiros | H31: 41251013929397000142550010000053251296202518 | I31: 45954 | J31: Cancelada
A32: 451 | B32: Netcom Construtora Ltda | C32: 4785.2 | D32: 5326 | E32: 4785.2 | F32: 5102 | G32: =VLOOKUP(F32,CFOP[],2,FALSE) -> Venda de mercadoria adquirida ou recebida de terceiros | H32: 41251013929397000142550010000053261296202515 | I32: 45954 | J32: Emitida
A33: 447 | B33: Sindicato Dos Empregados Em Estabelecimentos | C33: 790 | D33: 5327 | E33: 790 | F33: 5101 | G33: =VLOOKUP(F33,CFOP[],2,FALSE) -> Venda de produção do estabelecimento | H33: 41251013929397000142550010000053271300202518 | I33: 45958 | J33: Cancelada
A34: 365 | B34: Volkswagen do Brasil Industria de Veiculos Automotores Ltda | C34: 32346.3 | D34: 5328 | E34: 27131.3 | F34: 5102 | G34: =VLOOKUP(F34,CFOP[],2,FALSE) -> Venda de mercadoria adquirida ou recebida de terceiros | H34: 41251013929397000142550010000053281302202512 | I34: 45960 | J34: Emitida
A35: 427 | B35: Sig Combibloc do Brasil Ltda | C35: 5629 | D35: 5329 | E35: 3379 | F35: 5102 | G35: =VLOOKUP(F35,CFOP[],2,FALSE) -> Venda de mercadoria adquirida ou recebida de terceiros | H35: 41251013929397000142550010000053291302202510 | I35: 45960 | J35: Emitida
A36: 431 | B36: Sig Combibloc do Brasil Ltda | C36: 3842.6 | D36: 5330 | E36: 1722.6 | F36: 5102 | G36: =VLOOKUP(F36,CFOP[],2,FALSE) -> Venda de mercadoria adquirida ou recebida de terceiros | H36: 41251013929397000142550010000053301302202510 | I36: 45960 | J36: Emitida
A37: 1201 | B37: Memphis Engenharia e Serviços Ltda | C37: 1342.45 | D37: 5331 | E37: 1342.45 | F37: 5102 | G37: =VLOOKUP(F37,CFOP[],2,FALSE) -> Venda de mercadoria adquirida ou recebida de terceiros | H37: 41251013929397000142550010000053311302202518 | I37: 45960 | J37: Emitida
A38: 447 | B38: Sindicato Dos Empregados Em Estabelecimentos | C38: 790 | D38: 5332 | E38: 790 | F38: 5102 | G38: =VLOOKUP(F38,CFOP[],2,FALSE) -> Venda de mercadoria adquirida ou recebida de terceiros | H38: 41251013929397000142550010000053321303202519 | I38: 45961 | J38: Emitida
A39: 1189 | B39: Gusto & Henri Supermercados Ltda | C39: 2711.6 | D39: 5333 | E39: 1731.6 | F39: 5102 | G39: =VLOOKUP(F39,CFOP[],2,FALSE) -> Venda de mercadoria adquirida ou recebida de terceiros | H39: 41251013929397000142550010000053331303202516 | I39: 45961 | J39: Emitida
A40: 460 | B40: Hergen S/A Maquinas e Equipamentos | C40: 4806 | D40: 5334 | E40: 4806 | F40: 6102 | G40: =VLOOKUP(F40,CFOP[],2,FALSE) -> Venda de mercadoria adquirida ou recebida de terceiros | H40: 41251113929397000142550010000053341306202518 | I40: 45964 | J40: Emitida
...

Sheet NFS-e NC
A1: OS | B1: CLIENTE | C1: TOTAL OS | D1: NFS-e | E1: VALOR NFS-e | F1: DPS | G1: CHAVE | H1: DATA | I1: STATUS | J1: OBSERVAÇÕES | K1: RETER ISS | L1: ISS | M1: RETER INSS | N1: INSS | O1: VALOR LIQUIDO | P1: PDFs | Q1: XML
A2: 1218 | B2: Araúz & Advogados Associados | C2: 790 | D2: 1 | E2: 790 | F2: 1 | G2: 41069022213929397000142000000000000125117375775122 | H2: 45967 | I2: Emitida | K2: NÃO | L2: =_xlfn.IFS(NFSe_NC[[#This Row],[RETER ISS]]="NÃO",0,NFSe_NC[[#This Row],[RETER ISS]]="SIM",NFSe_NC[[#This Row],[VALOR NFS-e]]*5%) -> 0 | M2: NÃO | N2: {=_xlfn.IFS(NFSe_NC[[#This Row],[RETER INSS]]="NÃO",0,NFSe_NC[[#This Row],[RETER INSS]]="SIM",NFSe_NC[[#This Row],[VALOR NFS-e]]*11%)} -> 0 | O2: =E2-L2-N2 -> 790 | P2: OK | Q2: OK
A3: 1169 | B3: Condominio Palladium Shopping Center Curitiba | C3: 2560 | D3: 2 | E3: 2560 | F3: 22 | G3: 41069022213929397000142000000000000225118251173793 | H3: 45967 | I3: Cancelada | K3: NÃO | L3: =_xlfn.IFS(NFSe_NC[[#This Row],[RETER ISS]]="NÃO",0,NFSe_NC[[#This Row],[RETER ISS]]="SIM",NFSe_NC[[#This Row],[VALOR NFS-e]]*5%) -> 0 | M3: NÃO | N3: {=_xlfn.IFS(NFSe_NC[[#This Row],[RETER INSS]]="NÃO",0,NFSe_NC[[#This Row],[RETER INSS]]="SIM",NFSe_NC[[#This Row],[VALOR NFS-e]]*11%)} -> 0 | O3: =E3-L3-N3 -> 2560 | P3: OK | Q3: OK
A4: 425 | B4: Mondelez Brasil Ltda | C4: 14975.47 | D4: 3 | E4: 4375 | F4: 4 | G4: 41069022213929397000142000000000000325110788795272 | H4: 45968 | I4: Emitida | K4: NÃO | L4: =_xlfn.IFS(NFSe_NC[[#This Row],[RETER ISS]]="NÃO",0,NFSe_NC[[#This Row],[RETER ISS]]="SIM",NFSe_NC[[#This Row],[VALOR NFS-e]]*5%) -> 0 | M4: NÃO | N4: {=_xlfn.IFS(NFSe_NC[[#This Row],[RETER INSS]]="NÃO",0,NFSe_NC[[#This Row],[RETER INSS]]="SIM",NFSe_NC[[#This Row],[VALOR NFS-e]]*11%)} -> 0 | O4: =E4-L4-N4 -> 4375 | P4: OK | Q4: OK
A5: 1169 | B5: Condominio Palladium Shopping Center Curitiba | C5: 2560 | D5: 4 | E5: 2560 | F5: 21 | G5: 41069022213929397000142000000000000425111637155713 | H5: 45968 | I5: Emitida | K5: NÃO | L5: =_xlfn.IFS(NFSe_NC[[#This Row],[RETER ISS]]="NÃO",0,NFSe_NC[[#This Row],[RETER ISS]]="SIM",NFSe_NC[[#This Row],[VALOR NFS-e]]*5%) -> 0 | M5: NÃO | N5: {=_xlfn.IFS(NFSe_NC[[#This Row],[RETER INSS]]="NÃO",0,NFSe_NC[[#This Row],[RETER INSS]]="SIM",NFSe_NC[[#This Row],[VALOR NFS-e]]*11%)} -> 0 | O5: =E5-L5-N5 -> 2560 | P5: OK | Q5: OK
A6: 427 | B6: Sig Combibloc do Brasil Ltda | C6: 5629 | D6: 5 | E6: 2250 | F6: 15 | G6: 41069022213929397000142000000000000525118270293201 | H6: 45968 | I6: Emitida | K6: NÃO | L6: =_xlfn.IFS(NFSe_NC[[#This Row],[RETER ISS]]="NÃO",0,NFSe_NC[[#This Row],[RETER ISS]]="SIM",NFSe_NC[[#This Row],[VALOR NFS-e]]*5%) -> 0 | M6: NÃO | N6: {=_xlfn.IFS(NFSe_NC[[#This Row],[RETER INSS]]="NÃO",0,NFSe_NC[[#This Row],[RETER INSS]]="SIM",NFSe_NC[[#This Row],[VALOR NFS-e]]*11%)} -> 0 | O6: =E6-L6-N6 -> 2250 | P6: OK | Q6: OK
A7: 431 | B7: Sig Combibloc do Brasil Ltda | C7: 3842.6 | D7: 6 | E7: 2120 | F7: 18 | G7: 41069022213929397000142000000000000625111428150643 | H7: 45968 | I7: Emitida | K7: NÃO | L7: =_xlfn.IFS(NFSe_NC[[#This Row],[RETER ISS]]="NÃO",0,NFSe_NC[[#This Row],[RETER ISS]]="SIM",NFSe_NC[[#This Row],[VALOR NFS-e]]*5%) -> 0 | M7: NÃO | N7: {=_xlfn.IFS(NFSe_NC[[#This Row],[RETER INSS]]="NÃO",0,NFSe_NC[[#This Row],[RETER INSS]]="SIM",NFSe_NC[[#This Row],[VALOR NFS-e]]*11%)} -> 0 | O7: =E7-L7-N7 -> 2120 | P7: OK | Q7: OK
A8: 450 | B8: In Haus Industrial e Serviços de Logistica S/A | C8: 1280 | D8: 7 | E8: 1280 | F8: 13 | G8: 41069022213929397000142000000000000725115942115278 | H8: 45971 | I8: Emitida | K8: NÃO | L8: =_xlfn.IFS(NFSe_NC[[#This Row],[RETER ISS]]="NÃO",0,NFSe_NC[[#This Row],[RETER ISS]]="SIM",NFSe_NC[[#This Row],[VALOR NFS-e]]*5%) -> 0 | M8: NÃO | N8: {=_xlfn.IFS(NFSe_NC[[#This Row],[RETER INSS]]="NÃO",0,NFSe_NC[[#This Row],[RETER INSS]]="SIM",NFSe_NC[[#This Row],[VALOR NFS-e]]*11%)} -> 0 | O8: =E8-L8-N8 -> 1280 | P8: OK | Q8: OK
A9: 1227 | B9: Triermach Comércio e Serviços Ltda | C9: 1613 | D9: 8 | E9: 890 | F9: 24 | G9: 41069022213929397000142000000000000825110283723868 | H9: 45971 | I9: Emitida | K9: NÃO | L9: =_xlfn.IFS(NFSe_NC[[#This Row],[RETER ISS]]="NÃO",0,NFSe_NC[[#This Row],[RETER ISS]]="SIM",NFSe_NC[[#This Row],[VALOR NFS-e]]*5%) -> 0 | M9: NÃO | N9: {=_xlfn.IFS(NFSe_NC[[#This Row],[RETER INSS]]="NÃO",0,NFSe_NC[[#This Row],[RETER INSS]]="SIM",NFSe_NC[[#This Row],[VALOR NFS-e]]*11%)} -> 0 | O9: =E9-L9-N9 -> 890 | P9: OK | Q9: OK
A10: 390 | B10: Sig Combibloc do Brasil Ltda | C10: 3586.3 | D10: 9 | E10: 1687.5 | F10: 19 | G10: 41069022213929397000142000000000000925113078331188 | H10: 45971 | I10: Emitida | K10: NÃO | L10: =_xlfn.IFS(NFSe_NC[[#This Row],[RETER ISS]]="NÃO",0,NFSe_NC[[#This Row],[RETER ISS]]="SIM",NFSe_NC[[#This Row],[VALOR NFS-e]]*5%) -> 0 | M10: NÃO | N10: {=_xlfn.IFS(NFSe_NC[[#This Row],[RETER INSS]]="NÃO",0,NFSe_NC[[#This Row],[RETER INSS]]="SIM",NFSe_NC[[#This Row],[VALOR NFS-e]]*11%)} -> 0 | O10: =E10-L10-N10 -> 1687.5 | P10: OK | Q10: OK
A11: - | B11: Manusa do Brasil Comércio de Portas Automáticas Ltda | C11: 9579.43 | D11: 10 | E11: 9579.43 | F11: 25 | G11: 41069022213929397000142000000000001025116941085540 | H11: 45972 | I11: Cancelada | J11: Comissão | K11: NÃO | L11: =_xlfn.IFS(NFSe_NC[[#This Row],[RETER ISS]]="NÃO",0,NFSe_NC[[#This Row],[RETER ISS]]="SIM",NFSe_NC[[#This Row],[VALOR NFS-e]]*5%) -> 0 | M11: NÃO | N11: {=_xlfn.IFS(NFSe_NC[[#This Row],[RETER INSS]]="NÃO",0,NFSe_NC[[#This Row],[RETER INSS]]="SIM",NFSe_NC[[#This Row],[VALOR NFS-e]]*11%)} -> 0 | O11: =E11-L11-N11 -> 9579.43 | P11: OK | Q11: OK
A12: - | B12: Manusa do Brasil Comércio de Portas Automáticas Ltda | C12: 9579.43 | D12: 11 | E12: 9579.43 | F12: 26 | G12: 41069022213929397000142000000000001125117443559895 | H12: 45972 | I12: Emitida | J12: Comissão | K12: NÃO | L12: =_xlfn.IFS(NFSe_NC[[#This Row],[RETER ISS]]="NÃO",0,NFSe_NC[[#This Row],[RETER ISS]]="SIM",NFSe_NC[[#This Row],[VALOR NFS-e]]*5%) -> 0 | M12: NÃO | N12: {=_xlfn.IFS(NFSe_NC[[#This Row],[RETER INSS]]="NÃO",0,NFSe_NC[[#This Row],[RETER INSS]]="SIM",NFSe_NC[[#This Row],[VALOR NFS-e]]*11%)} -> 0 | O12: =E12-L12-N12 -> 9579.43 | P12: OK | Q12: OK
A13: 1096 | B13: In Haus Industrial e Serviços de Logistica S/A | C13: 1588 | D13: 12 | E13: 890 | F13: 27 | G13: 41069022213929397000142000000000001225117010358200 | H13: 45973 | I13: Emitida | K13: NÃO | L13: =_xlfn.IFS(NFSe_NC[[#This Row],[RETER ISS]]="NÃO",0,NFSe_NC[[#This Row],[RETER ISS]]="SIM",NFSe_NC[[#This Row],[VALOR NFS-e]]*5%) -> 0 | M13: NÃO | N13: {=_xlfn.IFS(NFSe_NC[[#This Row],[RETER INSS]]="NÃO",0,NFSe_NC[[#This Row],[RETER INSS]]="SIM",NFSe_NC[[#This Row],[VALOR NFS-e]]*11%)} -> 0 | O13: =E13-L13-N13 -> 890 | P13: OK | Q13: OK
A14: 115 | B14: Mondelez Brasil Ltda | C14: 5420 | D14: 13 | E14: 5420 | F14: 28 | G14: 41069022213929397000142000000000001325115679178519 | H14: 45973 | I14: Emitida | K14: NÃO | L14: =_xlfn.IFS(NFSe_NC[[#This Row],[RETER ISS]]="NÃO",0,NFSe_NC[[#This Row],[RETER ISS]]="SIM",NFSe_NC[[#This Row],[VALOR NFS-e]]*5%) -> 0 | M14: NÃO | N14: {=_xlfn.IFS(NFSe_NC[[#This Row],[RETER INSS]]="NÃO",0,NFSe_NC[[#This Row],[RETER INSS]]="SIM",NFSe_NC[[#This Row],[VALOR NFS-e]]*11%)} -> 0 | O14: =E14-L14-N14 -> 5420 | P14: OK | Q14: OK
A15: 317 | B15: Mondelez Brasil Ltda | C15: 1590 | D15: 14 | E15: 1590 | F15: 29 | G15: 41069022213929397000142000000000001425116388855460 | H15: 45973 | I15: Emitida | K15: NÃO | L15: =_xlfn.IFS(NFSe_NC[[#This Row],[RETER ISS]]="NÃO",0,NFSe_NC[[#This Row],[RETER ISS]]="SIM",NFSe_NC[[#This Row],[VALOR NFS-e]]*5%) -> 0 | M15: NÃO | N15: {=_xlfn.IFS(NFSe_NC[[#This Row],[RETER INSS]]="NÃO",0,NFSe_NC[[#This Row],[RETER INSS]]="SIM",NFSe_NC[[#This Row],[VALOR NFS-e]]*11%)} -> 0 | O15: =E15-L15-N15 -> 1590 | P15: OK | Q15: OK
A16: 365 | B16: Volkswagen do Brasil Industria de Veiculos Automotores Ltda | C16: 32346.3 | D16: 15 | E16: 4595 | F16: 7 | G16: 41069022213929397000142000000000001525117354140338 | H16: 45973 | I16: Cancelada | J16: Reemitida na OS #1276 | K16: SIM | L16: =_xlfn.IFS(NFSe_NC[[#This Row],[RETER ISS]]="NÃO",0,NFSe_NC[[#This Row],[RETER ISS]]="SIM",NFSe_NC[[#This Row],[VALOR NFS-e]]*5%) -> 229.75 | M16: NÃO | N16: {=_xlfn.IFS(NFSe_NC[[#This Row],[RETER INSS]]="NÃO",0,NFSe_NC[[#This Row],[RETER INSS]]="SIM",NFSe_NC[[#This Row],[VALOR NFS-e]]*11%)} -> 0 | O16: =E16-L16-N16 -> 4365.25 | P16: OK | Q16: OK
A17: 1151 | B17: Slaviero Empreendimentos Hoteleiros Ltda | C17: 5053 | D17: 16 | E17: 4330 | F17: 30 | G17: 41069022213929397000142000000000001625112163985832 | H17: 45974 | I17: Emitida | K17: NÃO | L17: =_xlfn.IFS(NFSe_NC[[#This Row],[RETER ISS]]="NÃO",0,NFSe_NC[[#This Row],[RETER ISS]]="SIM",NFSe_NC[[#This Row],[VALOR NFS-e]]*5%) -> 0 | M17: NÃO | N17: {=_xlfn.IFS(NFSe_NC[[#This Row],[RETER INSS]]="NÃO",0,NFSe_NC[[#This Row],[RETER INSS]]="SIM",NFSe_NC[[#This Row],[VALOR NFS-e]]*11%)} -> 0 | O17: =E17-L17-N17 -> 4330 | P17: OK | Q17: OK
A18: 401 | B18: Mondelez Brasil Ltda | C18: 33341.4 | D18: 17 | E18: 5660 | F18: 31 | G18: 41069022213929397000142000000000001725116555057780 | H18: 45974 | I18: Emitida | K18: NÃO | L18: =_xlfn.IFS(NFSe_NC[[#This Row],[RETER ISS]]="NÃO",0,NFSe_NC[[#This Row],[RETER ISS]]="SIM",NFSe_NC[[#This Row],[VALOR NFS-e]]*5%) -> 0 | M18: NÃO | N18: {=_xlfn.IFS(NFSe_NC[[#This Row],[RETER INSS]]="NÃO",0,NFSe_NC[[#This Row],[RETER INSS]]="SIM",NFSe_NC[[#This Row],[VALOR NFS-e]]*11%)} -> 0 | O18: =E18-L18-N18 -> 5660 | P18: OK | Q18: OK
A19: 1250 | B19: DVS Comércio de Veículos Ltda | C19: 890 | D19: 18 | E19: 890 | F19: 32 | G19: 41069022213929397000142000000000001825110120303986 | H19: 45979 | I19: Emitida | K19: NÃO | L19: =_xlfn.IFS(NFSe_NC[[#This Row],[RETER ISS]]="NÃO",0,NFSe_NC[[#This Row],[RETER ISS]]="SIM",NFSe_NC[[#This Row],[VALOR NFS-e]]*5%) -> 0 | M19: NÃO | N19: {=_xlfn.IFS(NFSe_NC[[#This Row],[RETER INSS]]="NÃO",0,NFSe_NC[[#This Row],[RETER INSS]]="SIM",NFSe_NC[[#This Row],[VALOR NFS-e]]*11%)} -> 0 | O19: =E19-L19-N19 -> 890 | P19: OK | Q19: OK
A20: 424 | B20: API SPE 46 - Planejamento e Desenvolvimento de Empr. Imob. | C20: 26180 | D20: 19 | E20: 15360 | F20: 33 | G20: 41069022213929397000142000000000001925119621385958 | H20: 45979 | I20: Emitida | J20: 1006/25 | K20: NÃO | L20: =_xlfn.IFS(NFSe_NC[[#This Row],[RETER ISS]]="NÃO",0,NFSe_NC[[#This Row],[RETER ISS]]="SIM",NFSe_NC[[#This Row],[VALOR NFS-e]]*5%) -> 0 | M20: NÃO | N20: {=_xlfn.IFS(NFSe_NC[[#This Row],[RETER INSS]]="NÃO",0,NFSe_NC[[#This Row],[RETER INSS]]="SIM",NFSe_NC[[#This Row],[VALOR NFS-e]]*11%)} -> 0 | O20: =E20-L20-N20 -> 15360 | P20: OK | Q20: OK
A21: 770 | B21: Gold Indústria e Comércio Ltda | C21: 10560 | D21: 20 | E21: 5100 | F21: 34 | G21: 41069022213929397000142000000000002025118467741801 | H21: 45980 | I21: Cancelada | K21: NÃO | L21: =_xlfn.IFS(NFSe_NC[[#This Row],[RETER ISS]]="NÃO",0,NFSe_NC[[#This Row],[RETER ISS]]="SIM",NFSe_NC[[#This Row],[VALOR NFS-e]]*5%) -> 0 | M21: NÃO | N21: {=_xlfn.IFS(NFSe_NC[[#This Row],[RETER INSS]]="NÃO",0,NFSe_NC[[#This Row],[RETER INSS]]="SIM",NFSe_NC[[#This Row],[VALOR NFS-e]]*11%)} -> 0 | O21: =E21-L21-N21 -> 5100 | P21: OK | Q21: OK
A22: 436 | B22: Renault do Brasil Ltda | C22: 5180 | D22: 21 | E22: 1820 | F22: 35 | G22: 41069022213929397000142000000000002125114966579148 | H22: 45980 | I22: Emitida | K22: NÃO | L22: =_xlfn.IFS(NFSe_NC[[#This Row],[RETER ISS]]="NÃO",0,NFSe_NC[[#This Row],[RETER ISS]]="SIM",NFSe_NC[[#This Row],[VALOR NFS-e]]*5%) -> 0 | M22: NÃO | N22: {=_xlfn.IFS(NFSe_NC[[#This Row],[RETER INSS]]="NÃO",0,NFSe_NC[[#This Row],[RETER INSS]]="SIM",NFSe_NC[[#This Row],[VALOR NFS-e]]*11%)} -> 0 | O22: =E22-L22-N22 -> 1820 | P22: OK | Q22: OK
A23: 1044 | B23: In Haus Industrial e Serviços de Logistica S/A | C23: 1126.76 | D23: 22 | E23: 1126.76 | F23: 36 | G23: 41069022213929397000142000000000002225115510460816 | H23: 45980 | I23: Emitida | K23: NÃO | L23: =_xlfn.IFS(NFSe_NC[[#This Row],[RETER ISS]]="NÃO",0,NFSe_NC[[#This Row],[RETER ISS]]="SIM",NFSe_NC[[#This Row],[VALOR NFS-e]]*5%) -> 0 | M23: NÃO | N23: {=_xlfn.IFS(NFSe_NC[[#This Row],[RETER INSS]]="NÃO",0,NFSe_NC[[#This Row],[RETER INSS]]="SIM",NFSe_NC[[#This Row],[VALOR NFS-e]]*11%)} -> 0 | O23: =E23-L23-N23 -> 1126.76 | P23: OK | Q23: OK
A24: 1185 | B24: In Haus Industrial e Serviços de Logistica S/A | C24: 1790 | D24: 23 | E24: 1790 | F24: 37 | G24: 41069022213929397000142000000000002325110338369340 | H24: 45980 | I24: Emitida | K24: NÃO | L24: =_xlfn.IFS(NFSe_NC[[#This Row],[RETER ISS]]="NÃO",0,NFSe_NC[[#This Row],[RETER ISS]]="SIM",NFSe_NC[[#This Row],[VALOR NFS-e]]*5%) -> 0 | M24: NÃO | N24: {=_xlfn.IFS(NFSe_NC[[#This Row],[RETER INSS]]="NÃO",0,NFSe_NC[[#This Row],[RETER INSS]]="SIM",NFSe_NC[[#This Row],[VALOR NFS-e]]*11%)} -> 0 | O24: =E24-L24-N24 -> 1790 | P24: OK | Q24: OK
A25: 1123 | B25: Mondelez Brasil Ltda | C25: 29734.3 | D25: 24 | E25: 6420 | F25: 38 | G25: 41069022213929397000142000000000002425110336852862 | H25: 45980 | I25: Emitida | K25: NÃO | L25: =_xlfn.IFS(NFSe_NC[[#This Row],[RETER ISS]]="NÃO",0,NFSe_NC[[#This Row],[RETER ISS]]="SIM",NFSe_NC[[#This Row],[VALOR NFS-e]]*5%) -> 0 | M25: NÃO | N25: {=_xlfn.IFS(NFSe_NC[[#This Row],[RETER INSS]]="NÃO",0,NFSe_NC[[#This Row],[RETER INSS]]="SIM",NFSe_NC[[#This Row],[VALOR NFS-e]]*11%)} -> 0 | O25: =E25-L25-N25 -> 6420 | P25: OK | Q25: OK
A26: 770 | B26: Gold Indústria e Comércio Ltda | C26: 10560 | D26: 25 | E26: 5100 | F26: 9 | G26: 41069022213929397000142000000000002525112114328296 | H26: 45982 | I26: Cancelada | K26: NÃO | L26: =_xlfn.IFS(NFSe_NC[[#This Row],[RETER ISS]]="NÃO",0,NFSe_NC[[#This Row],[RETER ISS]]="SIM",NFSe_NC[[#This Row],[VALOR NFS-e]]*5%) -> 0 | M26: NÃO | N26: {=_xlfn.IFS(NFSe_NC[[#This Row],[RETER INSS]]="NÃO",0,NFSe_NC[[#This Row],[RETER INSS]]="SIM",NFSe_NC[[#This Row],[VALOR NFS-e]]*11%)} -> 0 | O26: =E26-L26-N26 -> 5100 | P26: OK | Q26: OK
A27: 770 | B27: Gold Indústria e Comércio Ltda | C27: 10560 | D27: 26 | E27: 5100 | F27: 11 | G27: 41069022213929397000142000000000002625115450137440 | H27: 45982 | I27: Emitida | J27: Retenção ISS/INSS | K27: SIM | L27: =_xlfn.IFS(NFSe_NC[[#This Row],[RETER ISS]]="NÃO",0,NFSe_NC[[#This Row],[RETER ISS]]="SIM",NFSe_NC[[#This Row],[VALOR NFS-e]]*5%) -> 255 | M27: SIM | N27: {=_xlfn.IFS(NFSe_NC[[#This Row],[RETER INSS]]="NÃO",0,NFSe_NC[[#This Row],[RETER INSS]]="SIM",NFSe_NC[[#This Row],[VALOR NFS-e]]*11%)} -> 561 | O27: =E27-L27-N27 -> 4284 | P27: OK | Q27: OK
A28: 1259 | B28: Hospital Santa Cruz S/A | C28: 890 | D28: 27 | E28: 890 | F28: 39 | G28: 41069022213929397000142000000000002725117541231112 | H28: 45982 | I28: Cancelada | K28: NÃO | L28: =_xlfn.IFS(NFSe_NC[[#This Row],[RETER ISS]]="NÃO",0,NFSe_NC[[#This Row],[RETER ISS]]="SIM",NFSe_NC[[#This Row],[VALOR NFS-e]]*5%) -> 0 | M28: NÃO | N28: {=_xlfn.IFS(NFSe_NC[[#This Row],[RETER INSS]]="NÃO",0,NFSe_NC[[#This Row],[RETER INSS]]="SIM",NFSe_NC[[#This Row],[VALOR NFS-e]]*11%)} -> 0 | O28: =E28-L28-N28 -> 890 | P28: OK | Q28: OK
A29: 1263 | B29: Liga das Senhoras | C29: 890 | D29: 28 | E29: 890 | F29: 41 | G29: 41069022213929397000142000000000002825110054633963 | H29: 45985 | I29: Emitida | K29: NÃO | L29: =_xlfn.IFS(NFSe_NC[[#This Row],[RETER ISS]]="NÃO",0,NFSe_NC[[#This Row],[RETER ISS]]="SIM",NFSe_NC[[#This Row],[VALOR NFS-e]]*5%) -> 0 | M29: NÃO | N29: {=_xlfn.IFS(NFSe_NC[[#This Row],[RETER INSS]]="NÃO",0,NFSe_NC[[#This Row],[RETER INSS]]="SIM",NFSe_NC[[#This Row],[VALOR NFS-e]]*11%)} -> 0 | O29: =E29-L29-N29 -> 890 | P29: OK | Q29: OK
A30: 1145 | B30: Ebanx Ltda | C30: 16247.15 | D30: 29 | E30: 9800 | F30: 42 | G30: 41069022213929397000142000000000002925111848198190 | H30: 45985 | I30: Emitida | K30: NÃO | L30: =_xlfn.IFS(NFSe_NC[[#This Row],[RETER ISS]]="NÃO",0,NFSe_NC[[#This Row],[RETER ISS]]="SIM",NFSe_NC[[#This Row],[VALOR NFS-e]]*5%) -> 0 | M30: NÃO | N30: {=_xlfn.IFS(NFSe_NC[[#This Row],[RETER INSS]]="NÃO",0,NFSe_NC[[#This Row],[RETER INSS]]="SIM",NFSe_NC[[#This Row],[VALOR NFS-e]]*11%)} -> 0 | O30: =E30-L30-N30 -> 9800 | P30: OK | Q30: OK
A31: 1251 | B31: Callfarma Comércio de Medicamentos Ltda | C31: 1720 | D31: 30 | E31: 890 | F31: 43 | G31: 41069022213929397000142000000000003025110762653699 | H31: 45985 | I31: Emitida | K31: NÃO | L31: =_xlfn.IFS(NFSe_NC[[#This Row],[RETER ISS]]="NÃO",0,NFSe_NC[[#This Row],[RETER ISS]]="SIM",NFSe_NC[[#This Row],[VALOR NFS-e]]*5%) -> 0 | M31: NÃO | N31: {=_xlfn.IFS(NFSe_NC[[#This Row],[RETER INSS]]="NÃO",0,NFSe_NC[[#This Row],[RETER INSS]]="SIM",NFSe_NC[[#This Row],[VALOR NFS-e]]*11%)} -> 0 | O31: =E31-L31-N31 -> 890 | P31: OK | Q31: OK
A32: 1248 | B32: Hospital Union Ltda | C32: 980 | D32: 31 | E32: 980 | F32: 44 | G32: 41069022213929397000142000000000003125110071474581 | H32: 45985 | I32: Emitida | K32: NÃO | L32: =_xlfn.IFS(NFSe_NC[[#This Row],[RETER ISS]]="NÃO",0,NFSe_NC[[#This Row],[RETER ISS]]="SIM",NFSe_NC[[#This Row],[VALOR NFS-e]]*5%) -> 0 | M32: NÃO | N32: {=_xlfn.IFS(NFSe_NC[[#This Row],[RETER INSS]]="NÃO",0,NFSe_NC[[#This Row],[RETER INSS]]="SIM",NFSe_NC[[#This Row],[VALOR NFS-e]]*11%)} -> 0 | O32: =E32-L32-N32 -> 980 | P32: OK | Q32: OK
A33: 280 | B33: Graham Pack | C33: 32138.53 | D33: 32 | E33: 3000 | F33: 46 | G33: 41069022213929397000142000000000003225114199438898 | H33: 45987 | I33: Emitida | K33: NÃO | L33: =_xlfn.IFS(NFSe_NC[[#This Row],[RETER ISS]]="NÃO",0,NFSe_NC[[#This Row],[RETER ISS]]="SIM",NFSe_NC[[#This Row],[VALOR NFS-e]]*5%) -> 0 | M33: NÃO | N33: {=_xlfn.IFS(NFSe_NC[[#This Row],[RETER INSS]]="NÃO",0,NFSe_NC[[#This Row],[RETER INSS]]="SIM",NFSe_NC[[#This Row],[VALOR NFS-e]]*11%)} -> 0 | O33: =E33-L33-N33 -> 3000 | P33: OK | Q33: OK
A34: 1276 | B34: Volkswagen do Brasil Industria de Veiculos Automotores Ltda | C34: 32346.3 | D34: 33 | E34: 32346.3 | F34: 13 | G34: 41069022213929397000142000000000003325119683748322 | H34: 45987 | I34: Emitida | J34: Retenção ISS | K34: SIM | L34: =_xlfn.IFS(NFSe_NC[[#This Row],[RETER ISS]]="NÃO",0,NFSe_NC[[#This Row],[RETER ISS]]="SIM",NFSe_NC[[#This Row],[VALOR NFS-e]]*5%) -> 1617.315 | M34: NÃO | N34: {=_xlfn.IFS(NFSe_NC[[#This Row],[RETER INSS]]="NÃO",0,NFSe_NC[[#This Row],[RETER INSS]]="SIM",NFSe_NC[[#This Row],[VALOR NFS-e]]*11%)} -> 0 | O34: =E34-L34-N34 -> 30728.985 | P34: OK | Q34: OK
A35: - | B35: Manusa do Brasil Comércio de Portas Automáticas Ltda | C35: 9579.43 | D35: 34 | E35: 9579.43 | F35: 48 | G35: 41069022213929397000142000000000003425115012338300 | H35: 45988 | I35: Cancelada | J35: Comissão | K35: NÃO | L35: =_xlfn.IFS(NFSe_NC[[#This Row],[RETER ISS]]="NÃO",0,NFSe_NC[[#This Row],[RETER ISS]]="SIM",NFSe_NC[[#This Row],[VALOR NFS-e]]*5%) -> 0 | M35: NÃO | N35: {=_xlfn.IFS(NFSe_NC[[#This Row],[RETER INSS]]="NÃO",0,NFSe_NC[[#This Row],[RETER INSS]]="SIM",NFSe_NC[[#This Row],[VALOR NFS-e]]*11%)} -> 0 | O35: =E35-L35-N35 -> 9579.43 | P35: OK | Q35: OK
A36: - | B36: Manusa do Brasil Comércio de Portas Automáticas Ltda | C36: 20800.99 | D36: 35 | E36: 20800.99 | F36: 49 | G36: 41069022213929397000142000000000003525111147913761 | H36: 45988 | I36: Emitida | J36: Comissão | K36: NÃO | L36: =_xlfn.IFS(NFSe_NC[[#This Row],[RETER ISS]]="NÃO",0,NFSe_NC[[#This Row],[RETER ISS]]="SIM",NFSe_NC[[#This Row],[VALOR NFS-e]]*5%) -> 0 | M36: NÃO | N36: {=_xlfn.IFS(NFSe_NC[[#This Row],[RETER INSS]]="NÃO",0,NFSe_NC[[#This Row],[RETER INSS]]="SIM",NFSe_NC[[#This Row],[VALOR NFS-e]]*11%)} -> 0 | O36: =E36-L36-N36 -> 20800.99 | P36: OK | Q36: OK
A37: 1283 | B37: Filial 28 - Condor Super Center Ltda | C37: 920 | D37: 36 | E37: 920 | F37: 51 | G37: 41069022213929397000142000000000003625127767825850 | H37: 45992 | I37: Emitida | K37: NÃO | L37: =_xlfn.IFS(NFSe_NC[[#This Row],[RETER ISS]]="NÃO",0,NFSe_NC[[#This Row],[RETER ISS]]="SIM",NFSe_NC[[#This Row],[VALOR NFS-e]]*5%) -> 0 | M37: NÃO | N37: {=_xlfn.IFS(NFSe_NC[[#This Row],[RETER INSS]]="NÃO",0,NFSe_NC[[#This Row],[RETER INSS]]="SIM",NFSe_NC[[#This Row],[VALOR NFS-e]]*11%)} -> 0 | O37: =E37-L37-N37 -> 920 | P37: OK | Q37: OK
A38: 1284 | B38: Filial 01 - Condor Super Center Ltda | C38: 1315.7 | D38: 37 | E38: 650 | F38: 52 | G38: 41069022213929397000142000000000003725121359743937 | H38: 45992 | I38: Emitida | K38: NÃO | L38: =_xlfn.IFS(NFSe_NC[[#This Row],[RETER ISS]]="NÃO",0,NFSe_NC[[#This Row],[RETER ISS]]="SIM",NFSe_NC[[#This Row],[VALOR NFS-e]]*5%) -> 0 | M38: NÃO | N38: {=_xlfn.IFS(NFSe_NC[[#This Row],[RETER INSS]]="NÃO",0,NFSe_NC[[#This Row],[RETER INSS]]="SIM",NFSe_NC[[#This Row],[VALOR NFS-e]]*11%)} -> 0 | O38: =E38-L38-N38 -> 650 | P38: OK | Q38: OK
A39: 327 | B39: Renault do Brasil Ltda | C39: 6468.4 | D39: 38 | E39: 3550 | F39: 15 | G39: 41069022213929397000142000000000003825129068150343 | H39: 45992 | I39: Emitida | J39: Retenção ISS | K39: SIM | L39: =_xlfn.IFS(NFSe_NC[[#This Row],[RETER ISS]]="NÃO",0,NFSe_NC[[#This Row],[RETER ISS]]="SIM",NFSe_NC[[#This Row],[VALOR NFS-e]]*5%) -> 177.5 | M39: NÃO | N39: {=_xlfn.IFS(NFSe_NC[[#This Row],[RETER INSS]]="NÃO",0,NFSe_NC[[#This Row],[RETER INSS]]="SIM",NFSe_NC[[#This Row],[VALOR NFS-e]]*11%)} -> 0 | O39: =E39-L39-N39 -> 3372.5 | P39: OK | Q39: OK
A40: 976 | B40: Sig Combibloc do Brasil Ltda | C40: 1442.5 | D40: 39 | E40: 1442.5 | F40: 17 | G40: 41069022213929397000142000000000003925126737071427 | H40: 45992 | I40: Emitida | J40: Retenção ISS | K40: SIM | L40: =_xlfn.IFS(NFSe_NC[[#This Row],[RETER ISS]]="NÃO",0,NFSe_NC[[#This Row],[RETER ISS]]="SIM",NFSe_NC[[#This Row],[VALOR NFS-e]]*5%) -> 72.125 | M40: NÃO | N40: {=_xlfn.IFS(NFSe_NC[[#This Row],[RETER INSS]]="NÃO",0,NFSe_NC[[#This Row],[RETER INSS]]="SIM",NFSe_NC[[#This Row],[VALOR NFS-e]]*11%)} -> 0 | O40: =E40-L40-N40 -> 1370.375 | P40: OK | Q40: OK
...

Sheet Nice and Clean 
A1: OS | B1: CLIENTE | C1: TOTAL OS | D1: NF-e | E1: VALOR | F1: NFS-e | G1: DPS | H1: VALOR SERVIÇO | I1: REF | J1: XML | K1: PDF | L1: OK | M1: STATUS
A2: 5 | B2: Coopavel | C2: 24836.25 | D2: 1095 | E2: 24836.25 | F2: - | G2: - | H2: - | I2: - | J2: ok | K2: ok | L2: OK
A3: 1147 | B3: Coopavel | C3: 10023.15 | D3: 1096 | E3: 5056.75 | F3: - | G3: - | H3: - | I3: - | J3: ok | K3: ok | L3: OK
A4: 380 | B4: Duotec | C4: 15070.5 | D4: 1098 | E4: 13030.5 | H4: 2040 | I4: 0483/25 | J4: ok | K4: ok | L4: WAIT | M4: Emitir NFS-e
A5: 1088 | B5: API SBE 46 | C5: 1320 | D5: 1099 | E5: 870 | F5: 1 | G5: 1 | H5: 450 | I5: - | J5: ok | K5: ok | L5: OK
A6: 1090 | B6: Graffo | C6: 5700 | D6: 1100 | E6: 5700 | F6: - | G6: - | H6: - | I6: - | J6: ok | K6: ok | L6: OK
A7: 1091 | B7: Doacir F | C7: 2906.24 | D7: 1101 | E7: 2256.24 | F7: 2 | G7: 2 | H7: 650 | I7: - | J7: ok | K7: ok | L7: OK
A8: 1094 | B8: Casa de Carnes | C8: 1029 | D8: 1102 | E8: 1029 | F8: - | G8: - | H8: - | I8: - | J8: ok | K8: ok | L8: OK

Sheet NF-e Nice
A1: OS | B1: CLIENTE | C1: TOTAL OS | D1: NF-e | E1: VALOR NF-e | F1: CFOP | G1: NATUREZA | H1: CHAVE | I1: EMISSÃO | J1: STATUS | K1: OBSERVAÇÕES | L1: PDF | M1: XML
A2: 1 | B2: Industria de Produtos Suínos Casa Velha Ltda | C2: 1010 | D2: 1090 | E2: 860 | F2: 6102 | G2: =VLOOKUP(F2,CFOP[],2,FALSE) -> Venda de mercadoria adquirida ou recebida de terceiros | H2: 41251002797390000106550010000010901293202511 | I2: 45951 | J2: Cancelada
A3: 444 | B3: Seara Alimentos Ltda | C3: 6873.6 | D3: 1091 | E3: 6873.6 | F3: 6102 | G3: =VLOOKUP(F3,CFOP[],2,FALSE) -> Venda de mercadoria adquirida ou recebida de terceiros | H3: 41251002797390000106550010000010911293202519 | I3: 45951 | J3: Emitida
A4: 443 | B4: Ledur e Ledur Comercio de Alimentos Ltda | C4: 4510.8 | D4: 1092 | E4: 4510.8 | F4: 6102 | G4: =VLOOKUP(F4,CFOP[],2,FALSE) -> Venda de mercadoria adquirida ou recebida de terceiros | H4: 41251002797390000106550010000010921293202516 | I4: 45951 | J4: Emitida
A5: 1 | B5: Industria de Produtos Suínos Casa Velha Ltda | C5: 1010 | D5: 1093 | E5: 1010 | F5: 6102 | G5: =VLOOKUP(F5,CFOP[],2,FALSE) -> Venda de mercadoria adquirida ou recebida de terceiros | H5: 41251002797390000106550010000010931293202513 | I5: 45951 | J5: Emitida
A6: - | B6: MetalFim Tratamentos de Superficie Ltda | C6: 3915 | D6: 1094 | E6: 3915 | F6: 5901 | G6: =VLOOKUP(F6,CFOP[],2,FALSE) -> Remessa para industrialização por encomenda | H6: 41251102797390000106550010000010941307202516 | I6: 45965 | J6: Emitida
A7: 5 | B7: Coopavel Cooperativa Agroindustrial | C7: 24836.25 | D7: 1095 | E7: 24836.25 | F7: 5102 | G7: =VLOOKUP(F7,CFOP[],2,FALSE) -> Venda de mercadoria adquirida ou recebida de terceiros | H7: 41251102797390000106550010000010951310202510 | I7: 45968 | J7: Emitida
A8: 1087 | B8: Coopavel Cooperativa Agroindustrial | C8: 5056.75 | D8: 1096 | E8: 5056.75 | F8: 5102 | G8: =VLOOKUP(F8,CFOP[],2,FALSE) -> Venda de mercadoria adquirida ou recebida de terceiros | H8: 41251102797390000106550010000010961310202518 | I8: 45968 | J8: Emitida
A9: 1147 | B9: Coopavel Cooperativa Agroindustrial | C9: 5056.75 | D9: 1097 | E9: 5056.75 | F9: 5102 | G9: =VLOOKUP(F9,CFOP[],2,FALSE) -> Venda de mercadoria adquirida ou recebida de terceiros | H9: 41251102797390000106550010000010971322202515 | I9: 45980 | J9: Emitida
A10: 380 | B10: Duotec Engenharia Ltda | C10: 15070.5 | D10: 1098 | E10: 13030.5 | F10: 5102 | G10: =VLOOKUP(F10,CFOP[],2,FALSE) -> Venda de mercadoria adquirida ou recebida de terceiros | H10: 41251102797390000106550010000010981328202514 | I10: 45986 | J10: Emitida
A11: 1088 | B11: API SPE 46 - Planejamento E Desenvolvimento De Empr. Imob. | C11: 1320 | D11: 1099 | E11: 870 | F11: 5102 | G11: =VLOOKUP(F11,CFOP[],2,FALSE) -> Venda de mercadoria adquirida ou recebida de terceiros | H11: 41251202797390000106550010000010991337202514 | I11: 45995 | J11: Emitida
A12: 1090 | B12: Graffo Paranaense de Embalagens Ltda | C12: 5700 | D12: 1100 | E12: 5700 | F12: 5102 | G12: =VLOOKUP(F12,CFOP[],2,FALSE) -> Venda de mercadoria adquirida ou recebida de terceiros | H12: 41251202797390000106550010000011001342202511 | I12: 46000 | J12: Emitida
A13: 1091 | B13: Doacir F Rodrigues da Silva & Cia Ltda | C13: 2906.24 | D13: 1101 | E13: 2256.24 | F13: 5102 | G13: =VLOOKUP(F13,CFOP[],2,FALSE) -> Venda de mercadoria adquirida ou recebida de terceiros | H13: 41251202797390000106550010000011011348202510 | I13: 46006 | J13: Emitida
A14: 1094 | B14: Casa de Carne da Gente Ltda | C14: 1029 | D14: 1102 | E14: 1029 | F14: 5102 | G14: =VLOOKUP(F14,CFOP[],2,FALSE) -> Venda de mercadoria adquirida ou recebida de terceiros | H14: 41260102797390000106550010000011021282026011 | I14: 46051 | J14: Emitida
A15: 1101 | B15: Filial 49 - Condor Super Center Ltda | C15: 2415.28 | D15: 1103 | E15: 1885.28 | F15: 5102 | G15: =VLOOKUP(F15,CFOP[],2,FALSE) -> Venda de mercadoria adquirida ou recebida de terceiros | H15: 41260202797390000106550010000011031412026025 | I15: 46064 | J15: Emitida
A16: 1105 | B16: Filial 52 - Condor Super Center Ltda | C16: 1515.85 | D16: 1104 | E16: 1515.85 | F16: 6102 | G16: =VLOOKUP(F16,CFOP[],2,FALSE) -> Venda de mercadoria adquirida ou recebida de terceiros | H16: 41260302797390000106550010000011041612026038 | I16: 46084 | J16: Emitida
A17: 1108 | B17: Bassano Di Grappo Fundo de Investimento Imobiliário | C17: 17184.47 | D17: 1105 | E17: 15534.47 | F17: 6102 | G17: =VLOOKUP(F17,CFOP[],2,FALSE) -> Venda de mercadoria adquirida ou recebida de terceiros | H17: 41260302797390000106550010000011051672026031 | I17: 46090 | J17: Emitida
A18: 1107 | B18: Marcos Cesar Borba Montagens Ltda | C18: 7567.8 | D18: 1106 | E18: 7567.8 | F18: 5102 | G18: =VLOOKUP(F18,CFOP[],2,FALSE) -> Venda de mercadoria adquirida ou recebida de terceiros | H18: 41260302797390000106550010000011061742026032 | I18: 46097 | J18: Emitida
... A21: 1112 | B21: Selection Locadora de Veículos Ltda | C21: 39151.51 | D21: 1109 | E21: 36401.51 | F21: 5102 | G21: =VLOOKUP(F21,CFOP[],2,FALSE) -> Venda de mercadoria adquirida ou recebida de terceiros | H21: 41260402797390000106550010000011091103202601 | I21: 46126 | J21: Emitida

Sheet NFS-e Nice
A1: OS | B1: CLIENTE | C1: TOTAL OS | D1: NFS-e | E1: VALOR NFS-e | F1: DPS | G1: CHAVE | H1: DATA | I1: STATUS | J1: OBSERVAÇÕES | K1: RETER ISS | L1: ISS | M1: RETER INSS | N1: INSS | O1: VALOR LIQUIDO | P1: PDFs | Q1: XML
A2: 1088 | B2: API SPE 46 - Planejamento E Desenvolvimento De Empr. Imob. | C2: 1320 | D2: 1 | E2: 450 | F2: 1 | G2: 41069022202797390000106000000000000125125288126319 | H2: 45995 | I2: Emitida | J2: Retenção INSS | K2: NÃO | L2: =_xlfn.IFS(NFSe_Nice[[#This Row],[RETER ISS]]="NÃO",0,NFSe_Nice[[#This Row],[RETER ISS]]="SIM",NFSe_Nice[[#This Row],[VALOR NFS-e]]*5%) -> 0 | M2: SIM | N2: {=_xlfn.IFS(NFSe_Nice[[#This Row],[RETER INSS]]="NÃO",0,NFSe_Nice[[#This Row],[RETER INSS]]="SIM",NFSe_Nice[[#This Row],[VALOR NFS-e]]*11%)} -> 49.5 | O2: =E2-L2-N2 -> 400.5 | P2: OK | Q2: OK
A3: 1091 | B3: Doacir F Rodrigues da Silva Cia Ltda | C3: 2906.24 | D3: 2 | E3: 650 | F3: 2 | G3: 41069022202797390000106000000000000225128353964296 | H3: 46006 | I3: Emitida | K3: NÃO | L3: =_xlfn.IFS(NFSe_Nice[[#This Row],[RETER ISS]]="NÃO",0,NFSe_Nice[[#This Row],[RETER ISS]]="SIM",NFSe_Nice[[#This Row],[VALOR NFS-e]]*5%) -> 0 | M3: NÃO | N3: {=_xlfn.IFS(NFSe_Nice[[#This Row],[RETER INSS]]="NÃO",0,NFSe_Nice[[#This Row],[RETER INSS]]="SIM",NFSe_Nice[[#This Row],[VALOR NFS-e]]*11%)} -> 0 | O3: =E3-L3-N3 -> 650 | P3: OK | Q3: OK
A4: 1101 | B4: Filial 49 - Condor Super Center Ltda | C4: 2415.28 | D4: 3 | E4: 530 | F4: 1 | G4: 41069022202797390000106000000000000326020647349057 | H4: 46064 | I4: Emitida | K4: NÃO | L4: =_xlfn.IFS(NFSe_Nice[[#This Row],[RETER ISS]]="NÃO",0,NFSe_Nice[[#This Row],[RETER ISS]]="SIM",NFSe_Nice[[#This Row],[VALOR NFS-e]]*5%) -> 0 | M4: NÃO | N4: {=_xlfn.IFS(NFSe_Nice[[#This Row],[RETER INSS]]="NÃO",0,NFSe_Nice[[#This Row],[RETER INSS]]="SIM",NFSe_Nice[[#This Row],[VALOR NFS-e]]*11%)} -> 0 | O4: =E4-L4-N4 -> 530
A5: 1108 | B5: Bassano Di Grappo Fundo de Investimento Imobiliário | C5: 17184.47 | D5: 4 | E5: 1650 | F5: 2 | G5: 41069022202797390000106000000000000426031604533300 | H5: 46090 | I5: Emitida | J5: Retenção INSS | K5: SIM | L5: =_xlfn.IFS(NFSe_Nice[[#This Row],[RETER ISS]]="NÃO",0,NFSe_Nice[[#This Row],[RETER ISS]]="SIM",NFSe_Nice[[#This Row],[VALOR NFS-e]]*5%) -> 82.5 | M5: SIM | N5: {=_xlfn.IFS(NFSe_Nice[[#This Row],[RETER INSS]]="NÃO",0,NFSe_Nice[[#This Row],[RETER INSS]]="SIM",NFSe_Nice[[#This Row],[VALOR NFS-e]]*11%)} -> 181.5 | O5: =E5-L5-N5 -> 1386
A6: 1117 | B6: JM Clean Comércio de Produtos de Higiene e Limpeza Ltda | C6: 9324.6 | D6: 5 | E6: 9324.6 | F6: 5 | G6: 41069022202797390000106000000000000526041117088175 | H6: 46119 | I6: Emitida | K6: NÃO | L6: =_xlfn.IFS(NFSe_Nice[[#This Row],[RETER ISS]]="NÃO",0,NFSe_Nice[[#This Row],[RETER ISS]]="SIM",NFSe_Nice[[#This Row],[VALOR NFS-e]]*5%) -> 0 | M6: NÃO | N6: {=_xlfn.IFS(NFSe_Nice[[#This Row],[RETER INSS]]="NÃO",0,NFSe_Nice[[#This Row],[RETER INSS]]="SIM",NFSe_Nice[[#This Row],[VALOR NFS-e]]*11%)} -> 0 | O6: =E6-L6-N6 -> 9324.6
A7: 1112 | B7: Selection Locadora de Veículos Ltda | C7: 39151.51 | D7: 6 | E7: 2750 | F7: 6 | G7: 41069022202797390000106000000000000626047957214659 | H7: 46127 | I7: Emitida | K7: NÃO | L7: =_xlfn.IFS(NFSe_Nice[[#This Row],[RETER ISS]]="NÃO",0,NFSe_Nice[[#This Row],[RETER ISS]]="SIM",NFSe_Nice[[#This Row],[VALOR NFS-e]]*5%) -> 0 | M7: NÃO | N7: {=_xlfn.IFS(NFSe_Nice[[#This Row],[RETER INSS]]="NÃO",0,NFSe_Nice[[#This Row],[RETER INSS]]="SIM",NFSe_Nice[[#This Row],[VALOR NFS-e]]*11%)} -> 0 | O7: =E7-L7-N7 -> 2750

Sheet Data
A1: CFOP | B1: DESCRIÇÃO | C1: REGIÃO | E1: PRODUTO | F1: VALOR M² | G1: PESO
A2: 1201 | B2: Devolução de venda de produção do estabelecimento | C2: Dentro do Estado | E2: Peça de PVC Cinza / Cristal / Cinza - Porta Flexdoor | F2: 790
A3: 1202 | B3: Devolução de venda de mercadoria adquirida ou recebida de terceiros | C3: Dentro do estado | E3: Porta Flexdoor Folha Simples (Até 1200mm Largura) | F3: 1590
A4: 2201 | B4: Devolução de venda de produção do estabelecimento | C4: Fora do Estado | E4: Porta Flexdoor Folha Dupla (De 1201mm a 3000mm) | F4: 1790
A5: 2202 | B5: Devolução de venda de mercadoria adquirida ou recebida de terceiros | C5: Fora do Estado | E5: Cortina em PVC Flexivel | F5: 260
A6: 5101 | B6: Venda de produção do estabelecimento | C6: Dentro do Estado | E6: Vidro Laminado Incolor 8mm | F6: 470 | G6: 20
A7: 5102 | B7: Venda de mercadoria adquirida ou recebida de terceiros | C7: Dentro do Estado | E7: Vidro Laminado Incolor 10mm | F7: 470 | G7: 25
A8: 5103 | B8: Venda de produção do estabelecimento efetuada fora do estabelecimento | C8: Dentro do Estado | E8: Vidro Laminado Incolor 12mm | F8: 570 | G8: 30
A9: 5107 | B9: Venda de produção do estabelecimento, destinada à Zona Franca de Manaus ou Áreas de Livre Comércio | C9: Dentro do Estado | E9: Vidro Laminado Incolor 15mm | F9: 620 | G9: 37.5
A10: 5403 | B10: Venda de mercadoria adquirida ou recebida de terceiros, sujeita ao regime de substituição tributária, cujo imposto já foi retido anteriormente ST | C10: Dentro do Estado | E10: Vidro Temperado Incolor 10mm | F10: 470 | G10: 25
